<?xml version="1.0"?>
<robot xmlns:xacro="http://www.ros.org/wiki/xacro">

  <material name="blue">
    <color rgba="0 0 0.8 1"/>
  </material>

  <material name="white">
    <color rgba="1 1 1 1"/>
  </material>

  <material name="black">
    <color rgba="0 0 0 1"/>
  </material>

  <!-- BASE LINK -->

  <link name="base_link"> 
  </link>

  <!-- BASE FOOTPRINT LINK -->

  <joint name="base_footprint_joint" type="fixed">
    <parent link="base_link"/>
    <child link="base_footprint"/>
    <origin xyz="0 0 -0.034" rpy="0 0 0"/>
  </joint>

  <link name="base_footprint"> 
  </link>

  <!-- LEFT WHEEL -->

  <joint name="left_wheel_joint" type="continuous">
    <parent link="base_link"/>
    <child link="left_wheel"/>
    <origin xyz="0 0.0925 0" rpy="0 0 0"/>
    <axis xyz="0 1 0"/>
  </joint>

  <link name="left_wheel">
    <inertial>
      <mass value="0.0333821225271399" />
      <inertia
        ixx="1.51685744453984E-05"
        ixy="-2.30914163385349E-16"
        ixz="2.16894475887513E-16"
        iyy="2.57515540706052E-05"
        iyz="-2.70455055241677E-15"
        izz="1.51685744479579E-05" />
    </inertial>
    <visual>
        <geometry>
            <mesh filename="file://$(find amr_e1)/meshes/left_wheel.STL" />
        </geometry>
        <material name="blue"/>
    </visual>
    <collision>
      <geometry>
         <mesh filename="file://$(find amr_e1)/meshes/left_wheel.STL" />
      </geometry>
    </collision>
  </link>

  <gazebo reference="left_wheel">
    <material>Gazebo/Blue</material>
  </gazebo>

  <!-- RIGHT WHEEL -->

  <joint name="right_wheel_joint" type="continuous">
    <parent link="base_link"/>
    <child link="right_wheel"/>
    <origin xyz="0 -0.0925 0" rpy="0 0 0"/>
    <axis xyz="0 1 0"/>
  </joint>

  <link name="right_wheel">
    <inertial>
      <mass value="0.0333821225271399" />
      <inertia
        ixx="1.51685744453984E-05"
        ixy="-2.30914163385349E-16"
        ixz="2.16894475887513E-16"
        iyy="2.57515540706052E-05"
        iyz="-2.70455055241677E-15"
        izz="1.51685744479579E-05" />
    </inertial>
    <visual>
        <geometry>
          <mesh filename="file://$(find amr_e1)/meshes/right_wheel.STL" />
        </geometry>
        <material name="blue"/>
    </visual>
    <collision>
      <geometry>
        <mesh filename="file://$(find amr_e1)/meshes/right_wheel.STL" />
      </geometry>
    </collision>
  </link>

  <gazebo reference="right_wheel">
    <material>Gazebo/Blue</material>
  </gazebo>

  <!-- CHASSIS -->

  <joint name="chassis_joint" type="fixed">
    <parent link="base_link"/>
    <child link="chassis"/>
    <origin xyz="0 0 0.044" rpy="0 0 0"/>
  </joint>

  <link name="chassis">
    <inertial>
      <mass value="1.3487596591116"/>
      <inertia
        ixx="0.00281287150423675"
        ixy="5.78437570016345E-07"
        ixz="6.19504266896338E-08"
        iyy="0.00479295396610166"
        iyz="-1.17216786826658E-07"
        izz="0.0074346797085334" />
    </inertial>
    <visual>
        <geometry>
          <mesh filename="file://$(find amr_e1)/meshes/chassis.STL" />
        </geometry>
        <material name="black"/>
    </visual>
    <collision>
      <geometry>
        <mesh filename="file://$(find amr_e1)/meshes/chassis.STL" />
      </geometry>
    </collision>
  </link>

  <gazebo reference="chassis">
    <material>Gazebo/Black</material>
  </gazebo>

  <!-- LASER -->

  <joint name="laser_frame_joint" type="fixed">
    <parent link="chassis"/>
    <child link="laser_frame"/>
    <origin xyz="0.07 0 0.109" rpy="0 0 1.57"/>
  </joint>

  <link name="laser_frame">
    <!--inertial>
      <mass value="0.0735134364636496" />
      <inertia
        ixx="2.39640865526284E-05"
        ixy="3.13526285545598E-07"
        ixz="1.07178663012494E-08"
        iyy="1.81430736265743E-05"
        iyz="-3.25184533276073E-07"
        izz="3.94410620943647E-05" />
    </inertial-->
    <visual>
        <geometry>
          <mesh filename="file://$(find amr_e1)/meshes/laser_frame.STL" />
        </geometry>
        <material name="black"/>
    </visual>
    <collision>
      <geometry>
        <mesh filename="file://$(find amr_e1)/meshes/laser_frame.STL" />
      </geometry>
    </collision>
     
  </link>

  <gazebo reference="laser_frame">
    <material>Gazebo/Black</material>  

    <sensor name="laser" type="ray">
      <pose> 0 0 0 0 0 0 </pose>
      <visualize>true</visualize>
      <update_rate>10</update_rate>
      <ray>
        <scan>
          <horizontal>
            <samples>360</samples>
            <min_angle>-3.14</min_angle>
            <max_angle>3.14</max_angle>
          </horizontal>
        </scan>
        <range>
         <min>0.3</min>
         <max>12</max>
        </range>
      </ray>
      <plugin name="laser_controller" filename="libgazebo_ros_ray_sensor.so">
        <ros>
          <argument>~/out:=scan</argument>
        </ros>
        <output_type>sensor_msgs/LaserScan</output_type>
        <frame_name>laser_frame</frame_name>
      </plugin>
    </sensor>
  </gazebo>

  <!-- CASTER WHEEL FRONT -->

  <joint name="caster_wheel_front_joint" type="fixed">
    <parent link="chassis"/>
    <child link="caster_wheel_front"/>
    <origin xyz="0.1 0 -0.056" rpy="0 0 0"/>
  </joint>

  <link name="caster_wheel_front">
    <inertial>
     <mass value="0.00525691859071285" />
     <inertia
        ixx="4.53691257411894E-07"
        ixy="-7.51434232968261E-22"
        ixz="-6.07401207374975E-13"
        iyy="4.00059086550854E-07"
        iyz="1.52481144911298E-22"
        izz="5.73411138036653E-07" />
    </inertial>
    <visual>
        <geometry>
          <mesh filename="file://$(find amr_e1)/meshes/caster_wheel_front.STL" />
        </geometry>
        <material name="white"/>
    </visual>
    <collision>
      <geometry>
        <mesh filename="file://$(find amr_e1)/meshes/caster_wheel_front.STL" />
      </geometry>
    </collision>
  </link>

  <gazebo reference="caster_wheel_front">
    <material>Gazebo/White</material>
    <mu1 value="0.001"/>
    <mu2 value="0.001"/>
  </gazebo>

  <!-- CASTER WHEEL BEHIND -->

  <joint name="caster_wheel_behind_joint" type="fixed">
    <parent link="chassis"/>
    <child link="caster_wheel_behind"/>
    <origin xyz="-0.1 0 -0.056" rpy="0 0 0"/>
  </joint>

  <link name="caster_wheel_behind">
    <inertial>
      <mass value="0.00525691859071285" />
      <inertia
        ixx="4.53691257411894E-07"
        ixy="-7.51434232968261E-22"
        ixz="-6.07401207374975E-13"
        iyy="4.00059086550854E-07"
        iyz="1.52481144911298E-22"
        izz="5.73411138036653E-07" />
    </inertial>
    <visual>
        <geometry>
          <mesh filename="file://$(find amr_e1)/meshes/caster_wheel_behind.STL" />
        </geometry>
        <material name="white"/>
    </visual>
    <collision>
      <geometry>
        <mesh filename="file://$(find amr_e1)/meshes/caster_wheel_behind.STL" />   
      </geometry>
    </collision>
  </link>

   <gazebo reference="caster_wheel_behind">
    <material>Gazebo/White</material>
    <mu1 value="0.001"/>
    <mu2 value="0.001"/>
  </gazebo>

  <!-- IMU -->

  <joint name="imu_link_joint" type="fixed">
    <parent link="chassis"/>
    <child link="imu_link"/>
    <origin xyz="0 0 0.0751" rpy="0 0 0"/>
  </joint>

  <link name="imu_link">
    <inertial>
      <mass value="0.000628851677164551" />
      <inertia
        ixx="2.84177895500374E-08"
        ixy="-4.57750731625297E-14"
        ixz="3.75278292675679E-14"
        iyy="1.06612939030683E-08"
        iyz="-4.25878192471527E-14"
        izz="3.75953504496463E-08" />
    </inertial>
    <visual>
        <geometry>
          <mesh filename="file://$(find amr_e1)/meshes/imu_link.STL" />
        </geometry>
        <material name="blue"/>
    </visual>
    <collision>
      <geometry>
        <mesh filename="file://$(find amr_e1)/meshes/imu_link.STL" />
      </geometry>
    </collision>
  </link>

  <gazebo reference="imu_link">
    <material>Gazebo/Blue</material>
  </gazebo>

</robot>
